<?xml version="1.0" ?>
<!-- =================================================================================== -->
<!-- |    This document was autogenerated by xacro from nu_urc_arm.xacro               | -->
<!-- |    EDITING THIS FILE BY HAND IS NOT RECOMMENDED                                 | -->
<!-- =================================================================================== -->
<robot name="nu_urc_arm" xmlns:xacro="http://www.ros.org/wiki/xacro">
  <!-- PI constant -->
  <!-- The dimensions of the arm base's linear rail system -->
  <!-- The dimensions of the arm base's swivel system -->
  <!-- The dimensions of first arm link -->
  <!-- The dimensions of the second arm link -->
  <!-- The displacement of first arm link with respect to the swivel base -->
  <!-- Joint Limits -->
  <link name="arm_prism_base">
    <visual>
      <geometry>
        <box size="1 1 1"/>
        <origin rpy="0.0 0.0 0.0" xyz="0.0 0.0 0.0"/>
      </geometry>
    </visual>
  </link>
  <link name="arm_swivel_base">
    <visual>
      <geometry>
        <box size="1 1 1"/>
        <origin rpy="0.0 0.0 0.0" xyz="0.0 0.0 0.0"/>
      </geometry>
    </visual>
  </link>
  <link name="arm_rot_0">
    <visual>
      <geometry>
        <box size="0.0381 0.0381 0.1524"/>
        <origin rpy="0.0 0.0 0.0" xyz="0.0 0.0 0.0"/>
      </geometry>
    </visual>
  </link>
  <link name="arm_rot_1">
    <visual>
      <geometry>
        <box size="0.0381 0.0381 0.1524"/>
        <origin rpy="0.0 0.0 0.0" xyz="0.0 0.0 0.0"/>
      </geometry>
    </visual>
  </link>
  <joint name="arm_prism_base_swivel_base" type="continuous">
    <parent link="arm_prism_base"/>
    <child link="arm_swivel_base"/>
    <origin rpy="0.0 0.0 0.0" xyz="0.0 0.0 1"/>
    <axis xyz="0 0 1"/>
  </joint>
  <joint name="arm_swivel_base_rot_0" type="revolute">
    <parent link="arm_swivel_base"/>
    <child link="arm_rot_0"/>
    <origin rpy="0.0 0.0 0.0" xyz="0.0 0.0 0.0254"/>
    <axis xyz="0 1 0"/>
    <limit effort="1000.0" lower="0" upper="3.1415926" velocity="3.1415926"/>
  </joint>
  <joint name="arm_rot_0_1" type="revolute">
    <parent link="arm_rot_0"/>
    <child link="arm_rot_1"/>
    <origin rpy="0.0 0.0 0.0" xyz="0.0 0.0 0.1524"/>
    <axis xyz="0 1 0"/>
    <limit effort="1000.0" lower="0" upper="3.1415926" velocity="3.1415926"/>
  </joint>
</robot>

